<?xml version="1.0"?>
<sdf version='1.6'>
  <model name='turtlebotROS'>
    <link name='base_footprint'>
      <pose frame=''>0 0 0 0 -0 0</pose>
      <inertial>
        <pose frame=''>-0.009496 1.3e-05 0.135573 0 -0 0</pose>
        <mass>4.9213</mass>
        <inertia>
          <ixx>0.142129</ixx>
          <ixy>-4.09257e-06</ixy>
          <ixz>0.0154899</ixz>
          <iyy>0.140784</iyy>
          <iyz>6.52071e-06</iyz>
          <izz>0.0801071</izz>
        </inertia>
      </inertial>
      <collision name='base_footprint_fixed_joint_lump__base_collision'>
        <pose frame=''>0 0 0.06969 0 -0 0</pose>
        <geometry>
          <cylinder>
            <length>0.10938</length>
            <radius>0.178</radius>
          </cylinder>
        </geometry>
      </collision>
      <collision name='base_footprint_fixed_joint_lump__camera_link_collision_1'>
        <pose frame=''>-0.118 0 0.2812 0 -0 0</pose>
        <geometry>
          <box>
            <size>0.07271 0.27794 0.073</size>
          </box>
        </geometry>
        <surface>
          <contact>
            <ode/>
          </contact>
          <friction>
            <ode/>
          </friction>
        </surface>
      </collision>
      <collision name='base_footprint_fixed_joint_lump__caster_back_link_collision_2'>
        <pose frame=''>-0.135 0 0.0192 -1.5708 0 0</pose>
        <geometry>
          <cylinder>
            <length>0.0176</length>
            <radius>0.017</radius>
          </cylinder>
        </geometry>
        <surface>
          <contact>
            <ode>
              <kp>1e+06</kp>
              <kd>100</kd>
              <max_vel>1</max_vel>
              <min_depth>0.001</min_depth>
            </ode>
          </contact>
          <friction>
            <ode>
              <mu>0</mu>
              <mu2>0</mu2>
            </ode>
          </friction>
        </surface>
      </collision>
      <collision name='base_footprint_fixed_joint_lump__caster_front_link_collision_3'>
        <pose frame=''>0.115 0 0.0172 -1.5708 0 0</pose>
        <geometry>
          <cylinder>
            <length>0.0176</length>
            <radius>0.017</radius>
          </cylinder>
        </geometry>
        <surface>
          <contact>
            <ode>
              <kp>1e+06</kp>
              <kd>100</kd>
              <max_vel>1</max_vel>
              <min_depth>0.001</min_depth>
            </ode>
          </contact>
          <friction>
            <ode>
              <mu>0</mu>
              <mu2>0</mu2>
            </ode>
          </friction>
        </surface>
      </collision>
      <collision name='base_footprint_fixed_joint_lump__plate_bottom_link_collision_4'>
        <pose frame=''>0 0 0.1408 0 -0 0</pose>
        <geometry>
          <cylinder>
            <length>0.006</length>
            <radius>0.17</radius>
          </cylinder>
        </geometry>
      </collision>
      <collision name='base_footprint_fixed_joint_lump__plate_middle_link_collision_5'>
        <pose frame=''>0 0 0.1976 0 -0 0</pose>
        <geometry>
          <cylinder>
            <length>0.006</length>
            <radius>0.17</radius>
          </cylinder>
        </geometry>
      </collision>
      <collision name='base_footprint_fixed_joint_lump__plate_top_link_collision_6'>
        <pose frame=''>0 0 0.4068 0 -0 0</pose>
        <geometry>
          <cylinder>
            <length>0.006</length>
            <radius>0.17</radius>
          </cylinder>
        </geometry>
      </collision>
      <collision name='base_footprint_fixed_joint_lump__pole_bottom_0_link_collision_7'>
        <pose frame=''>0.12 0.082 0.113 0 -0 0</pose>
        <geometry>
          <cylinder>
            <length>0.0492</length>
            <radius>0.006</radius>
          </cylinder>
        </geometry>
      </collision>
      <collision name='base_footprint_fixed_joint_lump__pole_bottom_1_link_collision_8'>
        <pose frame=''>0.055 0.12 0.113 0 -0 0</pose>
        <geometry>
          <cylinder>
            <length>0.0492</length>
            <radius>0.006</radius>
          </cylinder>
        </geometry>
      </collision>
      <collision name='base_footprint_fixed_joint_lump__pole_bottom_2_link_collision_9'>
        <pose frame=''>-0.055 0.12 0.113 0 -0 0</pose>
        <geometry>
          <cylinder>
            <length>0.0492</length>
            <radius>0.006</radius>
          </cylinder>
        </geometry>
      </collision>
      <collision name='base_footprint_fixed_joint_lump__pole_bottom_3_link_collision_10'>
        <pose frame=''>0.12 -0.082 0.113 0 -0 0</pose>
        <geometry>
          <cylinder>
            <length>0.0492</length>
            <radius>0.006</radius>
          </cylinder>
        </geometry>
      </collision>
      <collision name='base_footprint_fixed_joint_lump__pole_bottom_4_link_collision_11'>
        <pose frame=''>0.055 -0.12 0.113 0 -0 0</pose>
        <geometry>
          <cylinder>
            <length>0.0492</length>
            <radius>0.006</radius>
          </cylinder>
        </geometry>
      </collision>
      <collision name='base_footprint_fixed_joint_lump__pole_bottom_5_link_collision_12'>
        <pose frame=''>-0.055 -0.12 0.113 0 -0 0</pose>
        <geometry>
          <cylinder>
            <length>0.0492</length>
            <radius>0.006</radius>
          </cylinder>
        </geometry>
      </collision>
      <collision name='base_footprint_fixed_joint_lump__pole_kinect_0_link_collision_13'>
        <pose frame=''>-0.1024 0.098 0.2474 0 -0 0</pose>
        <geometry>
          <cylinder>
            <length>0.0936</length>
            <radius>0.006</radius>
          </cylinder>
        </geometry>
      </collision>
      <collision name='base_footprint_fixed_joint_lump__pole_kinect_1_link_collision_14'>
        <pose frame=''>-0.1024 -0.098 0.2474 0 -0 0</pose>
        <geometry>
          <cylinder>
            <length>0.0936</length>
            <radius>0.006</radius>
          </cylinder>
        </geometry>
      </collision>
      <collision name='base_footprint_fixed_joint_lump__pole_middle_0_link_collision_15'>
        <pose frame=''>0.0381 0.1505 0.1742 0 -0 0</pose>
        <geometry>
          <cylinder>
            <length>0.0608</length>
            <radius>0.006</radius>
          </cylinder>
        </geometry>
      </collision>
      <collision name='base_footprint_fixed_joint_lump__pole_middle_1_link_collision_16'>
        <pose frame=''>0.0381 -0.1505 0.1742 0 -0 0</pose>
        <geometry>
          <cylinder>
            <length>0.0608</length>
            <radius>0.006</radius>
          </cylinder>
        </geometry>
      </collision>
      <collision name='base_footprint_fixed_joint_lump__pole_middle_2_link_collision_17'>
        <pose frame=''>-0.0381 0.1505 0.1742 0 -0 0</pose>
        <geometry>
          <cylinder>
            <length>0.0608</length>
            <radius>0.006</radius>
          </cylinder>
        </geometry>
      </collision>
      <collision name='base_footprint_fixed_joint_lump__pole_middle_3_link_collision_18'>
        <pose frame=''>-0.0381 -0.1505 0.1742 0 -0 0</pose>
        <geometry>
          <cylinder>
            <length>0.0608</length>
            <radius>0.006</radius>
          </cylinder>
        </geometry>
      </collision>
      <collision name='base_footprint_fixed_joint_lump__pole_top_0_link_collision_19'>
        <pose frame=''>0.0381 0.1505 0.3022 0 -0 0</pose>
        <geometry>
          <cylinder>
            <length>0.2032</length>
            <radius>0.006</radius>
          </cylinder>
        </geometry>
      </collision>
      <collision name='base_footprint_fixed_joint_lump__pole_top_1_link_collision_20'>
        <pose frame=''>0.0381 -0.1505 0.3022 0 -0 0</pose>
        <geometry>
          <cylinder>
            <length>0.2032</length>
            <radius>0.006</radius>
          </cylinder>
        </geometry>
      </collision>
      <collision name='base_footprint_fixed_joint_lump__pole_top_2_link_collision_21'>
        <pose frame=''>-0.0381 0.1505 0.3022 0 -0 0</pose>
        <geometry>
          <cylinder>
            <length>0.2032</length>
            <radius>0.006</radius>
          </cylinder>
        </geometry>
      </collision>
      <collision name='base_footprint_fixed_joint_lump__pole_top_3_link_collision_22'>
        <pose frame=''>-0.0381 -0.1505 0.3022 0 -0 0</pose>
        <geometry>
          <cylinder>
            <length>0.2032</length>
            <radius>0.006</radius>
          </cylinder>
        </geometry>
      </collision>
      <visual name='base_footprint_fixed_joint_lump__base_link_visual'>
        <pose frame=''>0.001 0 0.06219 0 -0 0</pose>
        <geometry>
          <mesh>
            <scale>1 1 1</scale>
            <uri>model://turtlebotROS/meshes/main_body.dae</uri>
          </mesh>
        </geometry>
        <material>
          <script>
            <uri>__default__</uri>
            <name>__default__</name>
          </script>
        </material>
      </visual>
      <visual name='base_footprint_fixed_joint_lump__camera_link_visual_1'>
        <pose frame=''>-0.118 0 0.2812 0 -0 1.5708</pose>
        <geometry>
          <mesh>
            <scale>1 1 1</scale>
            <uri>model://turtlebotROS/meshes/sensors/kinect.dae</uri>
          </mesh>
        </geometry>
        <material>
          <script>
            <uri>__default__</uri>
            <name>__default__</name>
          </script>
        </material>
      </visual>
      <visual name='base_footprint_fixed_joint_lump__plate_bottom_link_visual_2'>
        <pose frame=''>0.02364 0 0.1408 0 -0 0</pose>
        <geometry>
          <mesh>
            <scale>1 1 1</scale>
            <uri>model://turtlebotROS/meshes/stacks/hexagons/plate_bottom.dae</uri>
          </mesh>
        </geometry>
      </visual>
      <visual name='base_footprint_fixed_joint_lump__plate_middle_link_visual_3'>
        <pose frame=''>-0.01364 0 0.1976 0 -0 0</pose>
        <geometry>
          <mesh>
            <scale>1 1 1</scale>
            <uri>model://turtlebotROS/meshes/stacks/hexagons/plate_middle.dae</uri>
          </mesh>
        </geometry>
      </visual>
      <visual name='base_footprint_fixed_joint_lump__plate_top_link_visual_4'>
        <pose frame=''>-0.01364 0 0.4068 0 -0 0</pose>
        <geometry>
          <mesh>
            <scale>1 1 1</scale>
            <uri>model://turtlebotROS/meshes/stacks/hexagons/plate_top.dae</uri>
          </mesh>
        </geometry>
      </visual>
      <visual name='base_footprint_fixed_joint_lump__pole_bottom_0_link_visual_5'>
        <pose frame=''>0.12 0.082 0.113 0 -0 0</pose>
        <geometry>
          <mesh>
            <scale>1 1 1</scale>
            <uri>model://turtlebotROS/meshes/stacks/hexagons/pole_bottom.dae</uri>
          </mesh>
        </geometry>
      </visual>
      <visual name='base_footprint_fixed_joint_lump__pole_bottom_1_link_visual_6'>
        <pose frame=''>0.055 0.12 0.113 0 -0 0</pose>
        <geometry>
          <mesh>
            <scale>1 1 1</scale>
            <uri>model://turtlebotROS/meshes/stacks/hexagons/pole_bottom.dae</uri>
          </mesh>
        </geometry>
      </visual>
      <visual name='base_footprint_fixed_joint_lump__pole_bottom_2_link_visual_7'>
        <pose frame=''>-0.055 0.12 0.113 0 -0 0</pose>
        <geometry>
          <mesh>
            <scale>1 1 1</scale>
            <uri>model://turtlebotROS/meshes/stacks/hexagons/pole_bottom.dae</uri>
          </mesh>
        </geometry>
      </visual>
      <visual name='base_footprint_fixed_joint_lump__pole_bottom_3_link_visual_8'>
        <pose frame=''>0.12 -0.082 0.113 0 -0 0</pose>
        <geometry>
          <mesh>
            <scale>1 1 1</scale>
            <uri>model://turtlebotROS/meshes/stacks/hexagons/pole_bottom.dae</uri>
          </mesh>
        </geometry>
      </visual>
      <visual name='base_footprint_fixed_joint_lump__pole_bottom_4_link_visual_9'>
        <pose frame=''>0.055 -0.12 0.113 0 -0 0</pose>
        <geometry>
          <mesh>
            <scale>1 1 1</scale>
            <uri>model://turtlebotROS/meshes/stacks/hexagons/pole_bottom.dae</uri>
          </mesh>
        </geometry>
      </visual>
      <visual name='base_footprint_fixed_joint_lump__pole_bottom_5_link_visual_10'>
        <pose frame=''>-0.055 -0.12 0.113 0 -0 0</pose>
        <geometry>
          <mesh>
            <scale>1 1 1</scale>
            <uri>model://turtlebotROS/meshes/stacks/hexagons/pole_bottom.dae</uri>
          </mesh>
        </geometry>
      </visual>
      <visual name='base_footprint_fixed_joint_lump__pole_kinect_0_link_visual_11'>
        <pose frame=''>-0.1024 0.098 0.2374 0 -0 0</pose>
        <geometry>
          <mesh>
            <scale>1 1 1</scale>
            <uri>model://turtlebotROS/meshes/sensors/sensor_pole.dae</uri>
          </mesh>
        </geometry>
      </visual>
      <visual name='base_footprint_fixed_joint_lump__pole_kinect_1_link_visual_12'>
        <pose frame=''>-0.1024 -0.098 0.2374 0 -0 0</pose>
        <geometry>
          <mesh>
            <scale>1 1 1</scale>
            <uri>model://turtlebotROS/meshes/sensors/sensor_pole.dae</uri>
          </mesh>
        </geometry>
      </visual>
      <visual name='base_footprint_fixed_joint_lump__pole_middle_0_link_visual_13'>
        <pose frame=''>0.0381 0.1505 0.1742 3.14159 -0 3.14159</pose>
        <geometry>
          <mesh>
            <scale>1 1 1</scale>
            <uri>model://turtlebotROS/meshes/stacks/hexagons/pole_middle.dae</uri>
          </mesh>
        </geometry>
      </visual>
      <visual name='base_footprint_fixed_joint_lump__pole_middle_1_link_visual_14'>
        <pose frame=''>0.0381 -0.1505 0.1742 3.14159 -0 3.14159</pose>
        <geometry>
          <mesh>
            <scale>1 1 1</scale>
            <uri>model://turtlebotROS/meshes/stacks/hexagons/pole_middle.dae</uri>
          </mesh>
        </geometry>
      </visual>
      <visual name='base_footprint_fixed_joint_lump__pole_middle_2_link_visual_15'>
        <pose frame=''>-0.0381 0.1505 0.1742 3.14159 -0 3.14159</pose>
        <geometry>
          <mesh>
            <scale>1 1 1</scale>
            <uri>model://turtlebotROS/meshes/stacks/hexagons/pole_middle.dae</uri>
          </mesh>
        </geometry>
      </visual>
      <visual name='base_footprint_fixed_joint_lump__pole_middle_3_link_visual_16'>
        <pose frame=''>-0.0381 -0.1505 0.1742 3.14159 -0 3.14159</pose>
        <geometry>
          <mesh>
            <scale>1 1 1</scale>
            <uri>model://turtlebotROS/meshes/stacks/hexagons/pole_middle.dae</uri>
          </mesh>
        </geometry>
      </visual>
      <visual name='base_footprint_fixed_joint_lump__pole_top_0_link_visual_17'>
        <pose frame=''>0.0381 0.1505 0.3022 0 -0 0</pose>
        <geometry>
          <mesh>
            <scale>1 1 1</scale>
            <uri>model://turtlebotROS/meshes/stacks/hexagons/pole_top.dae</uri>
          </mesh>
        </geometry>
      </visual>
      <visual name='base_footprint_fixed_joint_lump__pole_top_1_link_visual_18'>
        <pose frame=''>0.0381 -0.1505 0.3022 0 -0 0</pose>
        <geometry>
          <mesh>
            <scale>1 1 1</scale>
            <uri>model://turtlebotROS/meshes/stacks/hexagons/pole_top.dae</uri>
          </mesh>
        </geometry>
      </visual>
      <visual name='base_footprint_fixed_joint_lump__pole_top_2_link_visual_19'>
        <pose frame=''>-0.0381 0.1505 0.3022 0 -0 0</pose>
        <geometry>
          <mesh>
            <scale>1 1 1</scale>
            <uri>model://turtlebotROS/meshes/stacks/hexagons/pole_top.dae</uri>
          </mesh>
        </geometry>
      </visual>
      <visual name='base_footprint_fixed_joint_lump__pole_top_3_link_visual_20'>
        <pose frame=''>-0.0381 -0.1505 0.3022 0 -0 0</pose>
        <geometry>
          <mesh>
            <scale>1 1 1</scale>
            <uri>model://turtlebotROS/meshes/stacks/hexagons/pole_top.dae</uri>
          </mesh>
        </geometry>
      </visual>
      <velocity_decay/>
      <sensor name='bumpers' type='contact'>
        <always_on>1</always_on>
        <update_rate>50</update_rate>
        <visualize>1</visualize>
        <contact>
          <collision>base_footprint_fixed_joint_lump__base_collision</collision>
          <topic>__default_topic__</topic>
        </contact>
        <pose frame=''>0 0 0.0102 0 -0 0</pose>
      </sensor>
      <velocity_decay/>
      <sensor name='camera' type='depth'>
        <always_on>1</always_on>
        <update_rate>20</update_rate>
        <camera name='__default__'>
          <horizontal_fov>1.0472</horizontal_fov>
          <image>
            <format>B8G8R8</format>
            <width>640</width>
            <height>480</height>
          </image>
          <clip>
            <near>0.05</near>
            <far>8</far>
          </clip>
        </camera>
        <!--<plugin name='kinect_camera_controller' filename='libgazebo_ros_openni_kinect.so'>
          <cameraName>camera</cameraName>
          <alwaysOn>true</alwaysOn>
          <updateRate>10</updateRate>
          <imageTopicName>rgb/image_raw</imageTopicName>
          <depthImageTopicName>depth/image_raw</depthImageTopicName>
          <pointCloudTopicName>depth/points</pointCloudTopicName>
          <cameraInfoTopicName>rgb/camera_info</cameraInfoTopicName>
          <depthImageCameraInfoTopicName>depth/camera_info</depthImageCameraInfoTopicName>
          <frameName>camera_depth_optical_frame</frameName>
          <baseline>0.1</baseline>
          <distortion_k1>0.0</distortion_k1>
          <distortion_k2>0.0</distortion_k2>
          <distortion_k3>0.0</distortion_k3>
          <distortion_t1>0.0</distortion_t1>
          <distortion_t2>0.0</distortion_t2>
          <pointCloudCutoff>0.4</pointCloudCutoff>
        </plugin>-->
        <pose frame=''>-0.118 0 0.2812 0 -0 0</pose>
      </sensor>
      <velocity_decay/>
      <velocity_decay/>
      <velocity_decay/>
      <sensor name='cliff_sensor_front' type='ray'>
        <always_on>1</always_on>
        <update_rate>50</update_rate>
        <visualize>1</visualize>
        <ray>
          <scan>
            <horizontal>
              <samples>50</samples>
              <resolution>1</resolution>
              <min_angle>-0.0436</min_angle>
              <max_angle>0.0436</max_angle>
            </horizontal>
          </scan>
          <range>
            <min>0.01</min>
            <max>0.15</max>
            <resolution>1</resolution>
          </range>
        </ray>
        <pose frame=''>0.156 0 0.0316 3.14159 1.57079 3.14159</pose>
      </sensor>
      <velocity_decay/>
      <sensor name='cliff_sensor_left' type='ray'>
        <always_on>1</always_on>
        <update_rate>50</update_rate>
        <visualize>1</visualize>
        <ray>
          <scan>
            <horizontal>
              <samples>50</samples>
              <resolution>1</resolution>
              <min_angle>-0.0436</min_angle>
              <max_angle>0.0436</max_angle>
            </horizontal>
          </scan>
          <range>
            <min>0.01</min>
            <max>0.15</max>
            <resolution>1</resolution>
          </range>
        </ray>
        <pose frame=''>0.08734 0.13601 0.0316 3.14159 1.57079 3.14159</pose>
      </sensor>
      <velocity_decay/>
      <sensor name='cliff_sensor_right' type='ray'>
        <always_on>1</always_on>
        <update_rate>50</update_rate>
        <visualize>1</visualize>
        <ray>
          <scan>
            <horizontal>
              <samples>50</samples>
              <resolution>1</resolution>
              <min_angle>-0.0436</min_angle>
              <max_angle>0.0436</max_angle>
            </horizontal>
          </scan>
          <range>
            <min>0.01</min>
            <max>0.15</max>
            <resolution>1</resolution>
          </range>
        </ray>
        <pose frame=''>0.085 -0.13601 0.0316 3.14159 1.57079 3.14159</pose>
      </sensor>
      <gravity>1</gravity>
      <velocity_decay/>
      <sensor name='imu' type='imu'>
        <always_on>1</always_on>
        <update_rate>50</update_rate>
        <visualize>0</visualize>
        <imu>
          <angular_velocity>
            <x>
              <noise type='gaussian'>
                <mean>0</mean>
                <stddev>1.96e-06</stddev>
                <bias_mean>0</bias_mean>
                <bias_stddev>0</bias_stddev>
              </noise>
            </x>
            <y>
              <noise type='gaussian'>
                <mean>0</mean>
                <stddev>1.96e-06</stddev>
                <bias_mean>0</bias_mean>
                <bias_stddev>0</bias_stddev>
              </noise>
            </y>
            <z>
              <noise type='gaussian'>
                <mean>0</mean>
                <stddev>1.96e-06</stddev>
                <bias_mean>0</bias_mean>
                <bias_stddev>0</bias_stddev>
              </noise>
            </z>
          </angular_velocity>
          <linear_acceleration>
            <x>
              <noise type='gaussian'>
                <mean>0</mean>
                <stddev>0.017</stddev>
                <bias_mean>0.1</bias_mean>
                <bias_stddev>0.001</bias_stddev>
              </noise>
            </x>
            <y>
              <noise type='gaussian'>
                <mean>0</mean>
                <stddev>0.017</stddev>
                <bias_mean>0.1</bias_mean>
                <bias_stddev>0.001</bias_stddev>
              </noise>
            </y>
            <z>
              <noise type='gaussian'>
                <mean>0</mean>
                <stddev>0.017</stddev>
                <bias_mean>0.1</bias_mean>
                <bias_stddev>0.001</bias_stddev>
              </noise>
            </z>
          </linear_acceleration>
        </imu>
        <pose frame=''>0.056 0.062 0.0304 0 -0 0</pose>
      </sensor>

      
    </link>
    <link name='wheel_left_link'>
      <pose frame=''>0 0.115 0.0352 -1.5708 0 0</pose>
      <inertial>
        <pose frame=''>0 0 0 0 -0 0</pose>
        <mass>0.01</mass>
        <inertia>
          <ixx>0.001</ixx>
          <ixy>0</ixy>
          <ixz>0</ixz>
          <iyy>0.001</iyy>
          <iyz>0</iyz>
          <izz>0.001</izz>
        </inertia>
      </inertial>
      <collision name='wheel_left_link_collision'>
        <pose frame=''>0 0 0 0 -0 0</pose>
        <geometry>
          <cylinder>
            <length>0.0206</length>
            <radius>0.0352</radius>
          </cylinder>
        </geometry>
        <surface>
          <contact>
            <ode>
              <kp>1e+06</kp>
              <kd>100</kd>
              <max_vel>1</max_vel>
              <min_depth>0.001</min_depth>
            </ode>
          </contact>
          <friction>
            <ode>
              <mu>1</mu>
              <mu2>1</mu2>
            </ode>
          </friction>
        </surface>
      </collision>
      <visual name='wheel_left_link_visual'>
        <pose frame=''>0 0 0 0 -0 0</pose>
        <geometry>
          <mesh>
            <scale>1 1 1</scale>
            <uri>model://turtlebotROS/meshes/wheel.dae</uri>
          </mesh>
        </geometry>
        <material>
          <script>
            <uri>__default__</uri>
            <name>__default__</name>
          </script>
        </material>
      </visual>
      <gravity>1</gravity>
      <velocity_decay/>
    </link>
    <joint name='wheel_left_joint' type='revolute'>
      <child>wheel_left_link</child>
      <parent>base_footprint</parent>
      <axis>
        <xyz>0 1 0</xyz>
        <limit>
          <lower>-1e+16</lower>
          <upper>1e+16</upper>
        </limit>
        <dynamics>
          <spring_reference>0</spring_reference>
          <spring_stiffness>0</spring_stiffness>
        </dynamics>
        <use_parent_model_frame>1</use_parent_model_frame>
      </axis>
    </joint>
    <link name='wheel_right_link'>
      <pose frame=''>0 -0.115 0.0352 -1.5708 0 0</pose>
      <inertial>
        <pose frame=''>0 0 0 0 -0 0</pose>
        <mass>0.01</mass>
        <inertia>
          <ixx>0.001</ixx>
          <ixy>0</ixy>
          <ixz>0</ixz>
          <iyy>0.001</iyy>
          <iyz>0</iyz>
          <izz>0.001</izz>
        </inertia>
      </inertial>
      <collision name='wheel_right_link_collision'>
        <pose frame=''>0 0 0 0 -0 0</pose>
        <geometry>
          <cylinder>
            <length>0.0206</length>
            <radius>0.035</radius>
          </cylinder>
        </geometry>
        <surface>
          <contact>
            <ode>
              <kp>1e+06</kp>
              <kd>100</kd>
              <max_vel>1</max_vel>
              <min_depth>0.001</min_depth>
            </ode>
          </contact>
          <friction>
            <ode>
              <mu>1</mu>
              <mu2>1</mu2>
            </ode>
          </friction>
        </surface>
      </collision>
      <visual name='wheel_right_link_visual'>
        <pose frame=''>0 0 0 0 -0 0</pose>
        <geometry>
          <mesh>
            <scale>1 1 1</scale>
            <uri>model://turtlebotROS/meshes/wheel.dae</uri>
          </mesh>
        </geometry>
        <material>
          <script>
            <uri>__default__</uri>
            <name>__default__</name>
          </script>
        </material>
      </visual>
      <gravity>1</gravity>
      <velocity_decay/>
    </link>
    <joint name='wheel_right_joint' type='revolute'>
      <child>wheel_right_link</child>
      <parent>base_footprint</parent>
      <axis>
        <xyz>0 1 0</xyz>
        <limit>
          <lower>-1e+16</lower>
          <upper>1e+16</upper>
        </limit>
        <dynamics>
          <spring_reference>0</spring_reference>
          <spring_stiffness>0</spring_stiffness>
        </dynamics>
        <use_parent_model_frame>1</use_parent_model_frame>
      </axis>
    </joint>
    <static>0</static>
    <link name='camera_bottom_body_left'>
        <pose>-0.030000 0.076000 0.232400 -1.570000 0.000000 0.000000</pose>
        <inertial>
          <mass>0.500000</mass>
          <inertia>
            <ixx>1.000000</ixx>
            <ixy>0.000000</ixy>
            <ixz>0.000000</ixz>
            <iyy>1.000000</iyy>
            <iyz>0.000000</iyz>
            <izz>1.000000</izz>
         </inertia>
       </inertial>
        <visual name='visual'>
          <geometry>
            <mesh>
              <uri>model://turtlebotROS/meshes/sonyvid30/sonyvid30_bottom.dae</uri>
              <scale>4.000000 3.000000 3.000000</scale>
           </mesh>
         </geometry>
       </visual>
        <collision name='collision'>
          <geometry>
            <box>
              <size>0.100000 0.100000 0.100000</size>
           </box>
         </geometry>
          <surface>
            <friction>
              <ode>
                <mu>100000.000000</mu>
                <mu2>100000.000000</mu2>
                <slip1>0.000000</slip1>
                <slip2>0.000000</slip2>
             </ode>
           </friction>
            <bounce/>
            <contact>
              <ode/>
           </contact>
         </surface>
          <max_contacts>10</max_contacts>
       </collision>
        <velocity_decay>
          <linear>0.000000</linear>
          <angular>0.000000</angular>
       </velocity_decay>
        <self_collide>0</self_collide>
        <kinematic>0</kinematic>
        <gravity>1</gravity>
   </link>
    <link name='camera_column_body_left'>
        <pose>-0.020000 0.076000 0.247400 -1.570000 0.000000 0.000000</pose>
        <inertial>
          <mass>0.500000</mass>
          <inertia>
            <ixx>1.000000</ixx>
            <ixy>0.000000</ixy>
            <ixz>0.000000</ixz>
            <iyy>1.000000</iyy>
            <iyz>0.000000</iyz>
            <izz>1.000000</izz>
         </inertia>
       </inertial>
        <visual name='visual'>
          <geometry>
            <mesh>
              <uri>model://turtlebotROS/meshes/sonyvid30/sonyvid30_mid.dae</uri>
              <scale>0.600000 1.000000 1.000000</scale>
           </mesh>
         </geometry>
       </visual>
        <collision name='collision'>
          <geometry>
            <box>
              <size>0.100000 0.100000 0.100000</size>
           </box>
         </geometry>
          <surface>
            <friction>
              <ode>
                <mu>100000.000000</mu>
                <mu2>100000.000000</mu2>
                <slip1>0.000000</slip1>
                <slip2>0.000000</slip2>
             </ode>
           </friction>
            <bounce/>
            <contact>
              <ode/>
           </contact>
         </surface>
          <max_contacts>10</max_contacts>
       </collision>
        <velocity_decay>
          <linear>0.000000</linear>
          <angular>0.000000</angular>
       </velocity_decay>
        <self_collide>0</self_collide>
        <kinematic>0</kinematic>
        <gravity>1</gravity>
   </link>
    <link name='camera_top_body_left'>
        <pose>-0.050000 0.076000 0.242400 -1.570000 -0.000000 3.140000</pose>
        <inertial>
          <mass>0.500000</mass>
          <inertia>
            <ixx>1.000000</ixx>
            <ixy>0.000000</ixy>
            <ixz>0.000000</ixz>
            <iyy>1.000000</iyy>
            <iyz>0.000000</iyz>
            <izz>1.000000</izz>
         </inertia>
       </inertial>
        <sensor name='cam_turtlebot_left' type='camera'>
          <pose>0.000000 0.000000 0.000000 -1.570000 -0.000000 3.140000</pose>
          <update_rate>20.000000</update_rate>
          <camera name='__default__'>
            <horizontal_fov>1.570000</horizontal_fov>
            <image>
              <width>640</width>
              <height>480</height>
              <format>R8G8B8</format>
           </image>
            <clip>
              <near>0.300000</near>
              <far>15.000000</far>
           </clip>
         </camera>
         <plugin name="camera_controller_left" filename="libgazebo_ros_camera.so">
        <alwaysOn>true</alwaysOn>
        <updateRate>0.0</updateRate>
        <cameraName>TurtlebotROS/cameraL</cameraName>
        <imageTopicName>image_raw</imageTopicName>
        <cameraInfoTopicName>camera_info</cameraInfoTopicName>
        <frameName>camera_link</frameName>
        <hackBaseline>0.07</hackBaseline>
        <distortionK1>0.0</distortionK1>
        <distortionK2>0.0</distortionK2>
        <distortionK3>0.0</distortionK3>
        <distortionT1>0.0</distortionT1>
        <distortionT2>0.0</distortionT2>
      </plugin>
       </sensor>
        <visual name='visual'>
          <geometry>
            <mesh>
              <uri>model://turtlebotROS/meshes/sonyvid30/sonyvid30_top.dae</uri>
              <scale>2.000000 2.000000 1.300000</scale>
           </mesh>
         </geometry>
       </visual>
        <collision name='collision'>
          <geometry>
            <box>
              <size>0.100000 0.100000 0.100000</size>
           </box>
         </geometry>
          <surface>
            <friction>
              <ode>
                <mu>100000.000000</mu>
                <mu2>100000.000000</mu2>
                <slip1>0.000000</slip1>
                <slip2>0.000000</slip2>
             </ode>
           </friction>
            <bounce/>
            <contact>
              <ode/>
           </contact>
         </surface>
          <max_contacts>10</max_contacts>
       </collision>
        <velocity_decay>
          <linear>0.000000</linear>
          <angular>0.000000</angular>
       </velocity_decay>
        <self_collide>0</self_collide>
        <kinematic>0</kinematic>
        <gravity>1</gravity>
   </link>
    <link name='camera_bottom_body_right'>
        <pose>-0.030000 -0.076000 0.232400 -1.570000 0.000000 0.000000</pose>
        <inertial>
          <mass>0.500000</mass>
          <inertia>
            <ixx>1.000000</ixx>
            <ixy>0.000000</ixy>
            <ixz>0.000000</ixz>
            <iyy>1.000000</iyy>
            <iyz>0.000000</iyz>
            <izz>1.000000</izz>
         </inertia>
       </inertial>
        <visual name='visual'>
          <geometry>
            <mesh>
              <uri>model://turtlebotROS/meshes/sonyvid30/sonyvid30_bottom.dae</uri>
              <scale>4.000000 3.000000 3.000000</scale>
           </mesh>
         </geometry>
       </visual>
        <collision name='collision'>
          <geometry>
            <box>
              <size>0.100000 0.100000 0.100000</size>
           </box>
         </geometry>
          <surface>
            <friction>
              <ode>
                <mu>100000.000000</mu>
                <mu2>100000.000000</mu2>
                <slip1>0.000000</slip1>
                <slip2>0.000000</slip2>
             </ode>
           </friction>
            <bounce/>
            <contact>
              <ode/>
           </contact>
         </surface>
          <max_contacts>10</max_contacts>
       </collision>
        <velocity_decay>
          <linear>0.000000</linear>
          <angular>0.000000</angular>
       </velocity_decay>
        <self_collide>0</self_collide>
        <kinematic>0</kinematic>
        <gravity>1</gravity>
   </link>
    <link name='camera_column_body_right'>
        <pose>-0.020000 -0.076000 0.247400 -1.570000 0.000000 0.000000</pose>
        <inertial>
          <mass>0.500000</mass>
          <inertia>
            <ixx>1.000000</ixx>
            <ixy>0.000000</ixy>
            <ixz>0.000000</ixz>
            <iyy>1.000000</iyy>
            <iyz>0.000000</iyz>
            <izz>1.000000</izz>
         </inertia>
       </inertial>
        <visual name='visual'>
          <geometry>
            <mesh>
              <uri>model://turtlebotROS/meshes/sonyvid30/sonyvid30_mid.dae</uri>
              <scale>0.600000 1.000000 1.000000</scale>
           </mesh>
         </geometry>
       </visual>
        <collision name='collision'>
          <geometry>
            <box>
              <size>0.100000 0.100000 0.100000</size>
           </box>
         </geometry>
          <surface>
            <friction>
              <ode>
                <mu>100000.000000</mu>
                <mu2>100000.000000</mu2>
                <slip1>0.000000</slip1>
                <slip2>0.000000</slip2>
             </ode>
           </friction>
            <bounce/>
            <contact>
              <ode/>
           </contact>
         </surface>
          <max_contacts>10</max_contacts>
       </collision>
        <velocity_decay>
          <linear>0.000000</linear>
          <angular>0.000000</angular>
       </velocity_decay>
        <self_collide>0</self_collide>
        <kinematic>0</kinematic>
        <gravity>1</gravity>
   </link>
    <link name='camera_top_body_right'>
        <pose>-0.050000 -0.076000 0.242400 -1.570000 -0.000000 3.140000</pose>
        <inertial>
          <mass>0.500000</mass>
          <inertia>
            <ixx>1.000000</ixx>
            <ixy>0.000000</ixy>
            <ixz>0.000000</ixz>
            <iyy>1.000000</iyy>
            <iyz>0.000000</iyz>
            <izz>1.000000</izz>
         </inertia>
       </inertial>
        <sensor name='cam_turtlebot_right' type='camera'>
          <pose>0.000000 0.000000 0.000000 -1.570000 -0.000000 3.140000</pose>
          <update_rate>20.000000</update_rate>
          <camera name='__default__'>
            <horizontal_fov>1.570000</horizontal_fov>
            <image>
              <width>640</width>
              <height>480</height>
              <format>R8G8B8</format>
           </image>
            <clip>
              <near>0.300000</near>
              <far>15.000000</far>
           </clip>
         </camera>
         <plugin name="camera_controller_right" filename="libgazebo_ros_camera.so">
        <alwaysOn>true</alwaysOn>
        <updateRate>0.0</updateRate>
        <cameraName>TurtlebotROS/cameraR</cameraName>
        <imageTopicName>image_raw</imageTopicName>
        <cameraInfoTopicName>camera_info</cameraInfoTopicName>
        <frameName>camera_link</frameName>
        <hackBaseline>0.07</hackBaseline>
        <distortionK1>0.0</distortionK1>
        <distortionK2>0.0</distortionK2>
        <distortionK3>0.0</distortionK3>
        <distortionT1>0.0</distortionT1>
        <distortionT2>0.0</distortionT2>
      </plugin>
       </sensor>
        <visual name='visual'>
          <geometry>
            <mesh>
              <uri>model://turtlebotROS/meshes/sonyvid30/sonyvid30_top.dae</uri>
              <scale>2.000000 2.000000 1.300000</scale>
           </mesh>
         </geometry>
       </visual>
        <collision name='collision'>
          <geometry>
            <box>
              <size>0.100000 0.100000 0.100000</size>
           </box>
         </geometry>
          <surface>
            <friction>
              <ode>
                <mu>100000.000000</mu>
                <mu2>100000.000000</mu2>
                <slip1>0.000000</slip1>
                <slip2>0.000000</slip2>
             </ode>
           </friction>
            <bounce/>
            <contact>
              <ode/>
           </contact>
         </surface>
          <max_contacts>10</max_contacts>
       </collision>
        <velocity_decay>
          <linear>0.000000</linear>
          <angular>0.000000</angular>
       </velocity_decay>
        <self_collide>0</self_collide>
        <kinematic>0</kinematic>
        <gravity>1</gravity>
   </link>
   <link name='laser'>
        <pose>0.160000 0.000000 0.112000 0.000000 0.000000 0.000000</pose>
        <gravity>0</gravity>
        <inertial>
          <mass>0.100000</mass>
          <inertia>
            <ixx>1.000000</ixx>
            <ixy>0.000000</ixy>
            <ixz>0.000000</ixz>
            <iyy>1.000000</iyy>
            <iyz>0.000000</iyz>
            <izz>1.000000</izz>
         </inertia>
       </inertial>
        <visual name='visual'>
          <geometry>
            <mesh>
              <uri>model://hokuyo/meshes/hokuyo.dae</uri>
           </mesh>
         </geometry>
       </visual>
        <collision name='collision-base'>
          <pose>0.000000 0.000000 -0.014500 0.000000 0.000000 0.000000</pose>
          <geometry>
            <box>
              <size>0.050000 0.050000 0.041000</size>
           </box>
         </geometry>
          <max_contacts>10</max_contacts>
          <surface>
            <bounce/>
            <friction>
              <ode/>
           </friction>
            <contact>
              <ode/>
           </contact>
         </surface>
       </collision>
        <collision name='collision-top'>
          <pose>0.000000 0.000000 0.020500 0.000000 0.000000 0.000000</pose>
          <geometry>
            <cylinder>
              <radius>0.021000</radius>
              <length>0.029000</length>
           </cylinder>
         </geometry>
          <max_contacts>10</max_contacts>
          <surface>
            <bounce/>
            <friction>
              <ode/>
           </friction>
            <contact>
              <ode/>
           </contact>
         </surface>
       </collision>
        <sensor name='laser' type='ray'>
          <ray>
            <scan>
              <horizontal>
                <samples>180</samples>
                <resolution>1.000000</resolution>
                <min_angle>-1.570000</min_angle>
                <max_angle>1.570000</max_angle>
             </horizontal>
           </scan>
            <range>
              <min>0.080000</min>
              <max>10.000000</max>
              <resolution>0.010000</resolution>
           </range>
         </ray>
          <update_rate>20.000000</update_rate>
          <always_on>1</always_on>
          <visualize>1</visualize>
      <plugin name="gazebo_ros_head_hokuyo_controller" filename="libgazebo_ros_laser.so">
        <topicName>/turtlebotROS/laser/scan</topicName>
        <frameName>hokuyo_link</frameName>
      </plugin>
       </sensor>
        <velocity_decay>
          <linear>0.000000</linear>
          <angular>0.000000</angular>
       </velocity_decay>
        <self_collide>0</self_collide>
        <kinematic>0</kinematic>
   </link>
    <joint name='joint_laser' type='revolute'>
        <parent>base_footprint</parent>
        <child>laser</child>
        <axis>
          <xyz>0.000000 0.000000 0.000000</xyz>
          <limit>
            <lower>0.000000</lower>
            <upper>0.000000</upper>
         </limit>
       </axis>
   </joint>
   <joint name='pan_joint_left' type='revolute'>
        <pose>0.000000 0.000000 0.000000 0.000000 0.000000 0.000000</pose>
        <child>camera_bottom_body_left</child>
        <parent>camera_column_body_left</parent>
        <axis>
          <xyz>0.000000 1.000000 0.000000</xyz>
          <limit>
            <lower>0.000000</lower>
            <upper>0.000000</upper>
         </limit>
       </axis>
   </joint>
    <joint name='tilt_joint_left' type='revolute'>
        <pose>0.000000 0.000000 0.000000 0.000000 0.000000 0.000000</pose>
        <child>camera_column_body_left</child>
        <parent>camera_top_body_left</parent>
        <axis>
          <xyz>1.000000 0.000000 0.000000</xyz>
          <limit>
            <lower>0.000000</lower>
            <upper>0.000000</upper>
         </limit>
       </axis>
   </joint>
    <joint name='camera_left' type='revolute'>
        <pose>0.000000 0.000000 0.000000 0.000000 0.000000 0.000000</pose>
        <child>camera_bottom_body_left</child>
        <parent>base_footprint</parent>
        <axis>
          <xyz>0.000000 0.000000 0.000000</xyz>
          <limit>
            <lower>0.000000</lower>
            <upper>0.000000</upper>
         </limit>
       </axis>
   </joint>
    <joint name='pan_joint_right' type='revolute'>
        <pose>0.000000 0.000000 0.000000 0.000000 0.000000 0.000000</pose>
        <child>camera_bottom_body_right</child>
        <parent>camera_column_body_right</parent>
        <axis>
          <xyz>0.000000 1.000000 0.000000</xyz>
          <limit>
            <lower>0.000000</lower>
            <upper>0.000000</upper>
         </limit>
       </axis>
   </joint>
    <joint name='tilt_joint_right' type='revolute'>
        <pose>0.000000 0.000000 0.000000 0.000000 0.000000 0.000000</pose>
        <child>camera_column_body_right</child>
        <parent>camera_top_body_right</parent>
        <axis>
          <xyz>1.000000 0.000000 0.000000</xyz>
          <limit>
            <lower>0.000000</lower>
            <upper>0.000000</upper>
         </limit>
       </axis>
   </joint>
    <joint name='camera_right' type='revolute'>
        <pose>0.000000 0.000000 0.000000 0.000000 0.000000 0.000000</pose>
        <child>camera_bottom_body_right</child>
        <parent>base_footprint</parent>
        <axis>
          <xyz>0.000000 0.000000 0.000000</xyz>
          <limit>
            <lower>0.000000</lower>
            <upper>0.000000</upper>
         </limit>
       </axis>
   </joint>
    <plugin name='kobuki_controller' filename='libgazebo_ros_kobuki.so'>
      <publish_tf>1</publish_tf>
      <left_wheel_joint_name>wheel_left_joint</left_wheel_joint_name>
      <right_wheel_joint_name>wheel_right_joint</right_wheel_joint_name>
      <wheel_separation>.230</wheel_separation>
      <wheel_diameter>0.070</wheel_diameter>
      <torque>1.0</torque>
      <velocity_command_timeout>0.6</velocity_command_timeout>
      <cliff_sensor_left_name>cliff_sensor_left</cliff_sensor_left_name>
      <cliff_sensor_center_name>cliff_sensor_front</cliff_sensor_center_name>
      <cliff_sensor_right_name>cliff_sensor_right</cliff_sensor_right_name>
      <cliff_detection_threshold>0.04</cliff_detection_threshold>
      <bumper_name>bumpers</bumper_name>
      <imu_name>imu</imu_name>
    </plugin>
  </model>
</sdf>
